Workbook
Name _Data2: #REF!
Name A: #REF!
Name FSNo: #REF!
Name NotesGroup: OFFSET(#REF!,0,0,COUNTIF(#REF!,">"""))
Name SampleTable: #REF!
Name SR_NTE: #REF!
Name SR_PriorPeriod: #REF!
Name SR_ProcedureField: #REF!
Name SR_YesNo: #REF!
Name SRAssertion: #REF!
Name SRControlReliance: #REF!
Name SREntintyName: #REF!
Name SRExtent: #REF!
Name SRInherentRisk: #REF!
Name SRLineItem: #REF!
Name SRLineItemBalance: #REF!
Name SRNature: #REF!
Name SRPeriodEnd: #REF!
Name SRProcedures: #REF!
Name SRScopedItem: #REF!
Name SRScopedItemBalance: #REF!
Name SRSignificantRisk: #REF!
Name SRSubstantiveAlone: #REF!
Name SRSubstantiveResponseOrControlTest: #REF!
Name SRTiming: #REF!
Name SubTable: #REF!
Name TextRefCopy616: #REF!
Name TextRefCopy667: #REF!

Sheet I. Related parties
A1: Working papers (For internal reference only, not for submission to the tax authority) | Q1: BACK TO FULL APPENDIX I
A3: Company name: Hestra Matsuoka Vietnam Limited Liability Company
A4: Engagement: Preparation of Appendix I
A5: Fiscal year end: 31 December 2023
A7: THÔNG TIN VỀ CÁC BÊN LIÊN KẾT/ INFORMATION ON RELATED PARTIES
A9: STT | B9: Tên bên liên kết | C9: Quốc gia | D9: Mã số thuế | E9: Hình thức liên kết | P9: Ghi chú
A10: No. | B10: Name of related party | C10: Country | D10: Tax code | E10: Type of relationship | P10: Note
A11: (1) | B11: (2) | C11: (3) | D11: (4) | E11: (5) | P11: (6)
E12: A | F12: B | G12: C | H12: D | I12: Đ | J12: E | K12: G | L12: H | M12: I | N12: K | O12: L
A13: 1 | B13: Martin Magnusson & CO. AB | C13: Thụy Điển | D13: không có thông tin | E13: x | F13: x | H13: x | P13: + loại A: vì là công ty mẹ trực tiếp của Hestra Việt Nam; + loại B: vì đều là công ty con của công ty mẹ tối cao HESTRA-Handsken AB; + loại D: theo PBC năm nay: năm 2023, Hestra Việt Nam vay trung và dài hạn 100% từ Martin Magnusson & CO. AB, trung bình đầu và cuối kỳ của các khoản vay này (1.450.000 USD) lớn hơn 25% số vốn góp chủ sở hữu (3.500.000 USD).
A14: 2 | B14: Pinghu Hestra Trading Co., Ltd. | C14: Trung Quốc | D14: không có thông tin | F14: x | P14: Có chung công ty mẹ với HMV.
A15: 3 | B15: Hestra Hungary Kft. | C15: Hungary | D15: không có thông tin | F15: x | P15: Có chung công ty mẹ với HMV.
A16: 4 | B16: Hestra (Cambodia) Co., Ltd | C16: Cămpuchia | D16: không có thông tin | F16: x | P16: Bên liên kết mới trong năm. Có chung công ty mẹ với HMV. | Q16: New in CY
A17: 5 | B17: Eurogant Universal Limited | C17: Hồng Kông | D17: không có thông tin | F17: x | P17: Năm nay không có giao dịch | Q17: No transaction in CY

Sheet Financial Analysis
A2: Hestra Matsuoka Vietnam Co., Ltd
A4: Unit: VND | B4: Index | C4: 2023
C5: 31/12/2023
A6: Financial data from the Company's Audited Financial Statement
A7: Net Sales | B7: A | C7: =FS!D14 -> 210993426826
A8: Cost of Goods Sold (COGS) | B8: B | C8: =FS!D20 -> 179420682168
A9: Gross Profit/ (Loss) | B9: C=A-B | C9: =C7-C8 -> 31572744658
A10: Financial Income | B10: D | C10: =FS!D15 -> 89097554
A11: Financial Expenses | B11: E | C11: =FS!D21 -> 2178133594
A12: Selling Expenses | B12: F | C12: =FS!D23 -> 1288469364
A13: General and Administration Expenses | B13: G | C13: =FS!D24 -> 4083729286
A14: Operating Profit/ (Loss) | B14: H=C+D-E-F-G | C14: =C9+C10-C11-C12-C13 -> 24111509968
A15: Calculation of Profit Level Indicator
A16: Total Operating Income | B16: I=A+D | C16: =C7+C10 -> 211082524380
A17: Total Operating Expenses | B17: J=B+E+F+G | C17: =C8+C11+C12+C13 -> 186971014412
A19: Adjustment to Total Operating Income
A20: Financial Income | B20: D | C20: =C10 -> 89097554
A22: Adjusted Total Operating Income | B22: K=I-D | C22: =C16-C20 -> 210993426826
A24: Adjustment to Total Operating Expenses
A25: Financial Expenses | B25: =B11 -> E | C25: =C11 -> 2178133594
A27: Adjusted Total Operating Expenses | B27: L=J-E | C27: =C17-C25 -> 184792880818
A29: Adjusted Operating Profit/ (Loss) | B29: M=K-L | C29: =C22-C27 -> 26200546008
A31: Gross Margin | B31: C/A
A32: Gross Cost Plus | B32: C/B
A33: Operating Margin | B33: M/A
A34: Net Cost Plus | B34: M/L | C34: =C29/C27 -> 0.14178331
A37: Reconciliation formula | C37: =IF(C31=C68,"OK","to check") -> OK
A39: Công ty TNHH Hestra Matsuoka Việt Nam
A41: Đơn vị: Đồng Việt Nam | B41: Chú dẫn | C41: =C4 -> 2023
C42: =C5 -> 31/12/2023
A43: Dữ liệu tài chính từ Báo cáo tài chính đã kiểm toán của Công ty
A44: Doanh thu thuần | B44: A | C44: =C7 -> 210993426826
A45: Giá vốn hàng bán | B45: B | C45: =C8 -> 179420682168
A46: Lợi nhuận gộp | B46: C=A-B | C46: =C44-C45 -> 31572744658
A47: Doanh thu hoạt động tài chính | B47: D | C47: =C10 -> 89097554
A48: Chi phí tài chính | B48: E | C48: =C11 -> 2178133594
A49: Chi phí bán hàng | B49: F | C49: =C12 -> 1288469364
A50: Chi phí quản lý doanh nghiệp | B50: G | C50: =C13 -> 4083729286
A51: Lợi nhuận (lỗ) từ hoạt động sản xuất kinh doanh | B51: H=C+D-E-F-G | C51: =C46+C47-C48-C49-C50 -> 24111509968
A52: Bảng tính chỉ số tỷ suất lợi nhuận
...

Sheet FS
A1: Working papers (For internal reference only, not for submission to the tax authority) | G1: BACK TO SEGMENTED DATA
A3: Company name: Hestra Matsuoka Vietnam Limited Liability Company
A4: Engagement: Preparation of Appendix I
A5: Fiscal year end: 31 December 2023
A7: TÓM TẮT THÔNG TIN TÀI CHÍNH CỦA CÔNG TY/ SUMMARY OF FINANCIAL DATA OF THE COMPANY
A9: 1. Tổng giá trị giao dịch phát sinh từ hoạt động kinh doanh (Dòng I - Mục III của Phụ lục I) / Total transaction value incurred from business activities (Row I - Section III of Appendix I)
D10: 23842
A11: No./ STT | B11: Item/ Mục | C11: Value (USD)/ Giá trị (USD) (*) | D11: Value (VND)/ Giá trị (VNĐ) (*) | E11: KPMG's notes/ Lưu ý của KPMG
A12: 1 | B12: Doanh thu bán hàng và cung cấp dịch vụ/ Gross revenue | C12: 8849677 | D12: =D14 -> 210993426826
A13: 2 | B13: Các khoản giảm trừ doanh thu/ Revenue deductions | C13: 24 | D13: 0
A14: 3 | B14: Doanh thu thuần bán hàng và cung cấp dịch vụ/ Net revenue | C14: =C12-C13 -> 8849653 | D14: 210993426826
A15: 4 | B15: Doanh thu hoạt động tài chính/ Financial income | C15: 3737 | D15: 89097554
A16: a | B16: Lãi tiền gửi và lãi cho vay/ Interest income from deposits and loans | D16: 7844018 | E16: Thông tin chị Hương cung cấp ngày 27/3/2024 (329 USD)
A17: 5 | B17: Thu nhập khác/ Other income | C17: 1333 | D17: 31781386 | G17: =D19-D27 -> 24143291354
A18: 6 | B18: Các khoản thu hộ/ Receipts on behalf | C18: 0 | D18: 0
A19: 7 | B19: Tổng giá trị doanh thu bán ra cho các bên liên kết và các bên độc lập/ Total sales amount to related parties and third parties | C19: =C14+C15+C17-C18 -> 8854723 | D19: =D14+D15+D17-D18 -> 211114305766
A20: 8 | B20: Chi phí hàng hóa và dịch vụ mua vào/ Goods and services expense purchased | C20: 7525404 | D20: 179420682168 | E20: Note: Decree 132 requires the Company to disclose the purchasing value of goods and services. However, at the time of completion of this Form, this value was unavailable or could not be reliably calculated, as such Cost of Good Sold/Cost of Sales was used for declaration purpose.
A21: 9 | B21: Chi phí tài chính/ Financial expense | C21: 91357 | D21: 2178133594
A22: a | B22: Chi phí lãi vay/ Interest expense | C22: 74969 | D22: 1787410898
A23: 10 | B23: Chi phí bán hàng/ Selling expense | C23: 54042 | D23: 1288469364
A24: 11 | B24: Chi phí quản lý doanh nghiệp/ General and administration expense | C24: 171283 | D24: 4083729286
A25: 12 | B25: Chi phí khác/ Other expense | C25: 0 | D25: 0
A26: 13 | B26: Các khoản chi hộ/ Payments on behalf | C26: 0 | D26: 0 | E26: Do khoản chi hộ không hit vào P&L nên kê = 0 (last year's treatment)
A27: 14 | B27: Tổng giá trị chi phí phải trả cho các bên liên kết và các bên độc lập/ Total purchase amount from related parties and third parties | C27: =C20+C21+C23+C24+C25-C26 -> 7842086 | D27: =D20+D21+D23+D24+D25-D26 -> 186971014412
A29: (*) Source: HMV's audited financial statements for FY2023 and information from HMV.
A32: 2. Các mục khác tại Phần IV của Phụ lục I/ Other items in Section IV of Appendix I
D33: 23842
A34: No./ STT | B34: Item/ Mục | C34: Value (USD)/ Giá trị (USD) (*) | D34: Value (VND)/ Giá trị (VNĐ) (*) | E34: Lưu ý của KPMG/ KPMG's notes
A35: 1 | B35: Doanh thu bán hàng hóa, dịch vụ xuất khẩu/ Revenue from sales of exported goods and services | C35: 8849652.6 | D35: 210993426826
A36: 2 | B36: Chi phí khấu hao/ Depreciation and amortization expenses | C36: 157715 | D36: 3760241030 | E36: khớp so với số declared trên cashflow (3.760.241.030) | G36: TRUE
A38: (*) Source: HMV's audited financial statements for FY2023 and information from HMV.
A41: 3/ Tỷ suất lợi nhuận sử dụng xác định giá giao dịch liên kết/ Profit level indicators used to determine the transfer prices
B43: Unit: VND | C43: Index | D43: FY2023
B44: Net sales | C44: A | D44: =D14 -> 210993426826
B45: Cost of goods sold | C45: B | D45: =D20 -> 179420682168
B46: Gross profit | C46: C=A-B | D46: =D44-D45 -> 31572744658
B47: Selling expenses | C47: D | D47: =D23 -> 1288469364
B48: General and Administration expenses | C48: E | D48: =D24 -> 4083729286
B49: EBIT | C49: F=C-D-E | D49: =D46-D47-D48 -> 26200546008
B50: Gross Margin | C50: C/A | D50: =D46/D44 -> 0.14963852 | E50: 0.14963852
...

Sheet RPTs
A1: Hestra Matsuoka Vietnam Co., Ltd
A2: Summary of Related Party Transactions
A4: Transaction | B4: Related party | C4: Country | D4: Relationship | E4: Transaction Amount (VND) | F4: % of total net sales/total operating costs | G4: Pricing method (If information is available)
A5: ='III. Summary-RPTs'!C17 -> Purchase of raw materials and tools | B5: ='III. Summary-RPTs'!E17 -> Pinghu Hestra Trading Co., Ltd. | C5: China | D5: B | E5: ='III. Summary-RPTs'!J17 -> 6401721244 | F5: =E5/$E$17 -> 0.034239111
A6: ='III. Summary-RPTs'!C18 -> Sales of raw materials | B6: ='III. Summary-RPTs'!E18 -> Hestra Hungary Kft. | C6: =VLOOKUP(B6,'I. Related parties'!$B$13:$C$15,2,0) -> Hungary | D6: B | E6: ='III. Summary-RPTs'!H18 -> 503789089 | F6: =E6/$E$11 -> 0.0023877004
B7: ='III. Summary-RPTs'!E19 -> Hestra (Cambodia) Co., Ltd | C7: Cambodia | D7: B | E7: ='III. Summary-RPTs'!H19 -> 3165438205 | F7: =E7/$E$11 -> 0.015002544
A8: ='III. Summary-RPTs'!C34 -> Interest expense | B8: ='III. Summary-RPTs'!E34 -> Martin Magnusson & CO. AB | C8: Sweden | D8: A, B, D | E8: ='III. Summary-RPTs'!J34 -> 1787410898 | F8: =E8/$E$17 -> 0.0095598289
A9: ='III. Summary-RPTs'!C38 -> Provision of processing services | B9: ='III. Summary-RPTs'!E38 -> Martin Magnusson & CO. AB | C9: Sweden | D9: A, B, D | E9: ='III. Summary-RPTs'!H38 -> 207324199532 | F9: =E9/$E$11 -> 0.98260976
C11: Net Sales: | E11: ='Financial Analysis'!C7 -> 210993426826
C12: COGS: | E12: ='Financial Analysis'!C8 -> 179420682168
C13: Financial expense: | E13: ='Financial Analysis'!C11 -> 2178133594
C14: Selling expense: | E14: ='Financial Analysis'!C12 -> 1288469364
C15: G&A expense: | E15: ='Financial Analysis'!C13 -> 4083729286
C16: Other expense | E16: =FS!D25 -> 0
C17: Total costs: | E17: =SUM(E12:E16) -> 186971014412

Sheet III. Summary-RPTs
A1: Working papers (For internal reference only, not for submission to the tax authority) | P1: BACK TO FULL APPENDIX I
A3: Company name: Hestra Matsuoka Vietnam Limited Liability Company | P3: PP1 - Comparable Uncontrolled Price Method
A4: Engagement: Preparation of Appendix I | P4: PP2-1 - Resale Price Method
A5: Fiscal year end: 31 December 2023 | P5: PP2-2 - Cost Plus Method
P6: PP2-3 - Comparable Profit Method
A7: TÓM TẮT CÁC GIAO DỊCH LIÊN KẾT/ SUMMARY OF RELATED PARTY TRANSACTIONS | P7: PP3 - Profit Split Method
P8: Non-disclosure
A10: Chỉ tiêu theo Phụ lục I/ Item per Appendix I | B10: Loại giao dịch/ Transactions category | C10: Tên giao dịch (tiếng Anh)/ Name of transactions (English) | D10: Tên giao dịch (tiếng Việt)/ Name of transactions (Vietnamese) | E10: Tên của Bên liên kết (Tiếng Anh)/ Name of related party (English) | F10: Tên của Bên liên kết (Tiếng Việt)/ Name of related party (Vietnamese) | G10: Giá trị theo đồng nước ngoài/ Value in foreign currency | H10: Giá trị giao dịch (VND)/ (*) Transaction value (VND) | M10: Mô tả giao dịch và phương pháp xác định giá/ Description of transactions and transfer pricing methods | N10: Kê khai phương pháp xác định giá trên Phụ lục I/ Disclosure of transfer pricing method in Appendix I | O10: Lưu ý của KPMG/ KPMG's notes
H11: Giá trị bán ra/ Sale amount | J11: Giá trị mua vào/ Purchase amount | L11: Tổng thu hộ, chi hộ, phân bổ cơ sở thường trú/ Payment on behalf, receipt on behalf, allocation to permanent establishment
G12: 23842 | H12: Giá trị ghi nhận của giao dịch liên kết/ Recorded value of related party transactions | I12: Giá trị xác định lại theo giá giao dịch độc lập (**)/ Value reassessed based on arm's length price | J12: Giá trị ghi nhận của giao dịch liên kết/ Recorded value of related party transactions | K12: Giá trị xác định lại theo giá giao dịch độc lập (**)/ Value reassessed based on arm's length price
A13: (1) | B13: (2) | C13: (3) | D13: (4) | E13: (5) | G13: (6) | H13: (7) | I13: (8) | J13: (9) | K13: (10) | L13: (11) | M13: (12) | N13: (13) | O13: (14)
A14: 1.1 | B14: Hàng hoá hình thành TSCĐ/ Goods forming fixed assets | C14: E.g. Purchase of machineries and equipment | D14: Mua máy móc thiết bị | E14: Related party A | F14: Bên liên kết A
C15: E.g. Disposal of machineries and equipment | D15: Thanh lý máy móc thiết bị | E15: Related party B | F15: Bên liên kết B
A16: Tổng/ Sub-total | H16: =ROUND(SUM(H14:H15),0) -> 0 | I16: =ROUND(SUM(I14:I15),0) -> 0 | J16: =ROUND(SUM(J14:J15),0) -> 0 | K16: =ROUND(SUM(K14:K15),0) -> 0
A17: 1.2 | B17: Hàng hoá không hình thành TSCĐ/ Goods not forming fixed assets | C17: Purchase of raw materials and tools | D17: Mua nguyên vật liệu và công cụ dụng cụ | E17: Pinghu Hestra Trading Co., Ltd. | F17: Pinghu Hestra Trading Co., Ltd. | G17: 268506.05 | J17: 6401721244 | K17: =J17 -> 6401721244 | M17: In FY2023, HMV purchased auxiliary materials and tools from Pingu Hestra Trading. Although main materials were provided by MMAB, HMV had to purchase other auxiliary materials from other suppliers for processing purposes. Some of these auxiliary materials were not available in Vietnam and therefore, purchased from Pingu Hestra Trading. The transfer price was mutually agreed between HMV and the related parties, based on costs incurred when the related parties purchased the materials plus a certain mark-up. | N17: PP2-3 - Comparable Profit Method | O17: Treatment giống năm 2022, 100% là mua NVL & CCDC. Xác nhận bởi chị Hương (verbal) ngày 27/3/2024
C18: Sales of raw materials | D18: Thanh lý nguyên vật liệu | E18: Hestra Hungary Kft. | F18: =E18 -> Hestra Hungary Kft. | G18: 21130.32 | H18: 503789089 | I18: =H18 -> 503789089 | M18: In FY2023, HMV purchased raw materials from related parties & third-party suppliers. The unutilised marterials then got sold to Hestra Hungary. The selling price is based on the actual cost incurred by HMV without any mark-up. | N18: PP2-3 - Comparable Profit Method
C19: Sales of raw materials | D19: Thanh lý nguyên vật liệu | E19: Hestra (Cambodia) Co., Ltd | F19: =E19 -> Hestra (Cambodia) Co., Ltd | G19: 132767.31 | H19: 3165438205 | I19: =H19 -> 3165438205 | M19: In FY2023, HMV purchased raw materials from related parties & third-party suppliers. The unutilised marterials then got sold to Hestra Cambodia. The selling price is based on the actual cost incurred by HMV without any mark-up. | N19: PP2-3 - Comparable Profit Method | O19: Giao dịch mới với bên liên kết mới. Giao dịch bản chất giống với bên Hungary. Xác nhận bởi chị Hương (verbal) ngày 27/3/2024.
A20: Tổng/ Sub-total | H20: =ROUND(SUM(H17:H19),0) -> 3669227294 | I20: =ROUND(SUM(I17:I19),0) -> 3669227294 | J20: =ROUND(SUM(J17:J19),0) -> 6401721244 | K20: =ROUND(SUM(K17:K19),0) -> 6401721244
A21: Tổng hàng hóa/ Sub-total of Goods | H21: =ROUND(SUM(H20,H16),0) -> 3669227294 | I21: =ROUND(SUM(I20,I16),0) -> 3669227294 | J21: =ROUND(SUM(J20,J16),0) -> 6401721244 | K21: =ROUND(SUM(K20,K16),0) -> 6401721244
A22: 2.1 | B22: Nghiên cứu, phát triển/ Research and development | C22: E.g. Provision of research and development services | D22: Cung cấp dịch vụ nghiên cứu và phát triển | E22: Related party A | F22: Bên liên kết A
C23: E.g. Purchase of research and development services | D23: Mua dịch vụ nghiên cứu và phát triển | E23: Related party B | F23: Bên liên kết B
A24: Tổng/ Sub-total | H24: =ROUND(SUM(H22:H23),0) -> 0 | I24: =ROUND(SUM(I22:I23),0) -> 0 | J24: =ROUND(SUM(J22:J23),0) -> 0 | K24: =ROUND(SUM(K22:K23),0) -> 0
A25: 2.2 | B25: Quảng cáo, tiếp thị/ Advertising, marketing | C25: E.g. Provision of advertising and marketing services | D25: Cung cấp dịch vụ quảng cáo, tiếp thị | E25: Related party A | F25: Bên liên kết A
C26: E.g. Purchase of advertising and marketing services | D26: Mua dịch vụ quảng cáo, tiếp thị | E26: Related party B | F26: Bên liên kết B
A27: Tổng/ Sub-total | H27: =ROUND(SUM(H25:H26),0) -> 0 | I27: =ROUND(SUM(I25:I26),0) -> 0 | J27: =ROUND(SUM(J25:J26),0) -> 0 | K27: =ROUND(SUM(K25:K26),0) -> 0
A28: 2.3 | B28: Quản lý kinh doanh và tư vấn, đào tạo/ Business management and consulting, training | C28: E.g. Provision of consulting services | D28: Cung cấp dịch vụ tư vấn | E28: Related party A | F28: Bên liên kết A
C29: E.g Training service fee | D29: Phí dịch vụ đào tạo | E29: Related party B | F29: Bên liên kết B
A30: Tổng/ Sub-total | H30: =ROUND(SUM(H28:H29),0) -> 0 | I30: =ROUND(SUM(I28:I29),0) -> 0 | J30: =ROUND(SUM(J28:J29),0) -> 0 | K30: =ROUND(SUM(K28:K29),0) -> 0
A31: 2.4.1 | B31: Phí bản quyền và các khoản tương tự/ Royalties and the equivalents | C31: E.g. Royalty fee | D31: Thu phí bản quyền | E31: Related party A | F31: Bên liên kết A
C32: E.g. Payment of royalty fee | D32: Trả phí bản quyền | E32: Related party B | F32: Bên liên kết B
A33: Tổng/ Sub-total | H33: =ROUND(SUM(H31:H32),0) -> 0 | I33: =ROUND(SUM(I31:I32),0) -> 0 | J33: =ROUND(SUM(J31:J32),0) -> 0 | K33: =ROUND(SUM(K31:K32),0) -> 0
A34: 2.4.2 | B34: Lãi vay/ Loan Interest | C34: Interest expense | D34: Chi phí lãi vay | E34: Martin Magnusson & CO. AB | F34: Martin Magnusson & CO. AB | G34: 74969 | J34: 1787410898 | K34: =J34 -> 1787410898 | M34: HMV and MMAB entered into several loan agreements. The interest rate applied in the loan contracts were i) 7% per annum for the short term loan and ii) 3% - 3.5% for the long term loans. | N34: PP1 - Comparable Uncontrolled Price Method
A36: Tổng/ Sub-total | H36: =ROUND(SUM(H34:H35),0) -> 0 | I36: =ROUND(SUM(I34:I35),0) -> 0 | J36: =ROUND(SUM(J34:J35),0) -> 1787410898 | K36: =ROUND(SUM(K34:K35),0) -> 1787410898
A37: Tổng hoạt động tài chính/ Sub-total of finance activities | H37: =ROUND(SUM(H36,H33),0) -> 0 | I37: =ROUND(SUM(I36,I33),0) -> 0 | J37: =ROUND(SUM(J36,J33),0) -> 1787410898 | K37: =ROUND(SUM(K36,K33),0) -> 1787410898
A38: 2.5 | B38: Dịch vụ khác/ Other services | C38: Provision of processing services | D38: Doanh thu từ hoạt động gia công | E38: Martin Magnusson & CO. AB | F38: Martin Magnusson & CO. AB | G38: 8695755 | H38: 207324199532 | I38: =H38 -> 207324199532 | M38: HMV and MMAB entered into the Processing contract No. CO-18-0002 dated 10 January 2018, under which HMV performed production of 250,000 pairs of all types of gloves each year. Quality and glove types were defined in specific purchase orders. The related party purchased HMV’s products for resale to overseas third-party distributors. The transfer price was determined based on processing unit price including labor costs, materials, management costs, etc. incurred by HMV plus a certain mark-up. | N38: PP2-3 - Comparable Profit Method
A40: Tổng/ Sub-total | H40: =ROUND(SUM(H38:H39),0) -> 207324199532 | I40: =ROUND(SUM(I38:I39),0) -> 207324199532 | J40: =ROUND(SUM(J38:J39),0) -> 0 | K40: =ROUND(SUM(K38:K39),0) -> 0
A41: Tổng dịch vụ/ Sub-total of services | H41: =ROUND(SUM(H24,H27,H30,H37,H40),0) -> 207324199532 | I41: =ROUND(SUM(I24,I27,I30,I37,I40),0) -> 207324199532 | J41: =ROUND(SUM(J24,J27,J30,J37,J40),0) -> 1787410898 | K41: =ROUND(SUM(K24,K27,K30,K37,K40),0) -> 1787410898
B42: Tổng thu hộ, chi hộ, phân bổ cơ sở thường trú/ Payment on behalf, receipt on behalf, allocation to permanent establishment | C42: Payment on behalf for logistics expense | D42: Chi hộ chi phí vận tải | E42: Martin Magnusson & CO. AB | F42: Martin Magnusson & CO. AB
C44: Total amount taxpayer paying on related parties' behalf | D44: Tổng các khoản người nộp thuế chi hộ cho bên liên kết | G44: =SUM(G42:G43) -> 0 | L44: =ROUND(SUM(L42:L43),0) -> 0
C47: Total amount taxpayer's related parties receiving on taxpayer's behalf | D47: Tổng các khoản bên liên kết thu hộ cho người nộp thuế | G47: =SUM(G45:G46) -> 0 | L47: =ROUND(SUM(L45:L46),0) -> 0
...
